<?xml version="1.0"?>
<sdf version="1.9">
  <model name="mobile_bot">
    <static>false</static>
    <pose>0 0 0.1 0 0 0</pose>

    <!-- Base -->
    <link name="base_link">
      <inertial>
        <mass>8.0</mass>
        <inertia>
          <ixx>0.2</ixx><iyy>0.2</iyy><izz>0.2</izz>
        </inertia>
      </inertial>

      <collision name="base_collision">
        <geometry>
          <box><size>0.4 0.3 0.1</size></box>
        </geometry>
      </collision>

      <visual name="base_visual">
        <geometry>
          <box><size>0.4 0.3 0.1</size></box>
        </geometry>
      </visual>
    </link>

    <!-- Left wheel (cylinder axis aligned with Y by rolling 90deg about X) -->
    <link name="left_wheel">
      <pose>0 0.16 0.05 1.5708 0 0</pose>
      <inertial>
        <mass>0.5</mass>
        <inertia>
          <ixx>0.001</ixx><iyy>0.001</iyy><izz>0.001</izz>
        </inertia>
      </inertial>

      <collision name="collision">
        <geometry>
          <cylinder><radius>0.05</radius><length>0.02</length></cylinder>
        </geometry>
        <surface>
          <friction>
            <ode>
              <mu>2.0</mu><mu2>2.0</mu2>
            </ode>
          </friction>
        </surface>
      </collision>

      <visual name="visual">
        <geometry>
          <cylinder><radius>0.05</radius><length>0.02</length></cylinder>
        </geometry>
      </visual>
    </link>

    <!-- Right wheel -->
    <link name="right_wheel">
      <pose>0 -0.16 0.05 1.5708 0 0</pose>
      <inertial>
        <mass>0.5</mass>
        <inertia>
          <ixx>0.001</ixx><iyy>0.001</iyy><izz>0.001</izz>
        </inertia>
      </inertial>

      <collision name="collision">
        <geometry>
          <cylinder><radius>0.05</radius><length>0.02</length></cylinder>
        </geometry>
        <surface>
          <friction>
            <ode>
              <mu>2.0</mu><mu2>2.0</mu2>
            </ode>
          </friction>
        </surface>
      </collision>

      <visual name="visual">
        <geometry>
          <cylinder><radius>0.05</radius><length>0.02</length></cylinder>
        </geometry>
      </visual>
    </link>

    <!-- Caster wheel (ball) -->
    <link name="caster">
      <pose>-0.15 0 0.03 0 0 0</pose>
      <collision name="collision">
        <geometry>
          <sphere><radius>0.03</radius></sphere>
        </geometry>
        <surface>
          <friction>
            <ode>
              <mu>0.3</mu><mu2>0.3</mu2>
            </ode>
          </friction>
        </surface>
      </collision>
      <visual name="visual">
        <geometry>
          <sphere><radius>0.03</radius></sphere>
        </geometry>
      </visual>
    </link>

    <!-- Joints -->
    <joint name="left_wheel_joint" type="revolute">
      <parent>base_link</parent>
      <child>left_wheel</child>
      <axis>
        <xyz>0 1 0</xyz>
        <limit><lower>-1e16</lower><upper>1e16</upper></limit>
      </axis>
    </joint>

    <joint name="right_wheel_joint" type="revolute">
      <parent>base_link</parent>
      <child>right_wheel</child>
      <axis>
        <xyz>0 1 0</xyz>
        <limit><lower>-1e16</lower><upper>1e16</upper></limit>
      </axis>
    </joint>

    <joint name="caster_joint" type="ball">
      <parent>base_link</parent>
      <child>caster</child>
    </joint>

    <!-- DiffDrive -->
    <plugin filename="gz-sim-diff-drive-system" name="gz::sim::systems::DiffDrive">
      <left_joint>left_wheel_joint</left_joint>
      <right_joint>right_wheel_joint</right_joint>
      <wheel_separation>0.32</wheel_separation>
      <wheel_radius>0.05</wheel_radius>
      <topic>/cmd_vel</topic>
      <odom_topic>odom</odom_topic>
      <frame_id>base_link</frame_id>
      <child_frame_id>odom</child_frame_id>
      <update_rate>50</update_rate>
    </plugin>

  </model>
</sdf>
